Добавил файл в удалённом репозитории.
Создаем ошибку в локальном репозитории
for i in range(0, 10):
    print(i)
